Workbook

Sheet Observacoes
A1: id_mae | B1: Potencial (0-3) | C1: Type | D1: Observations
A2: OBS-001 | B2: 0 | C2: Infraestrutura | D2: Falta de computadores/tablets para todos os funcionarios
A3: OBS-002 | B3: 0 | C3: Infraestrutura | D3: Dificuldade de comunicacao com profissionais da ala oeste
A4: OBS-003 | B4: 0 | C4: Infraestrutura | D4: Falta de pivo na ala oeste
A5: OBS-004 | B5: 0 | C5: Infraestrutura | D5: Excesso de demandas que desfocam o profissional do pivo (excesso de telefonemas)
A6: OBS-005 | B6: 0 | C6: Infraestrutura | D6: Ramais insuficientes
A7: OBS-006 | B7: 0 | C7: Infraestrutura | D7: Sistema de transporte vacuo inativo
A8: OBS-007 | B8: 0 | C8: CERNER | D8: SIsitema para checagem de medicacoes juntas em mesma via pelo Cerner
A9: OBS-008 | B9: 0 | C9: Infraestrutura | D9: Bloqueio da vista natural dos quartos por aparelho de de pressao negativa
A10: OBS-009 | B10: 0 | C10: Infraestrutura | D10: PIXYS: Problemas de filas em momentos-chave do dia, problemas de reposicao, disponibilidade de material e medicamentos.
A11: OBS-010 | B11: 0 | C11: Infraestrutura | D11: Solicitacao de medicacao para farmacia central por papel escaneado
A12: OBS-011 | B12: 0 | C12: Infraestrutura | D12: Corredor congestionado por equipamentos
A13: OBS-012 | B13: 0 | C13: Infraestrutura | D13: Lentidao na saida de exames por falta de priorizacao e regulacao
A14: OBS-013 | B14: 0 | C14: Infraestrutura | D14: Equipe de transporte reduzida
A15: OBS-014 | B15: 0 | D15: Acionamentos indevidos por parte dos familiares em comunicacao interna do quarto
A16: OBS-015 | B16: 0 | D16: Alta demanda da profissional do pivo (dupla checagem antes de acionar algum profissional)
A17: OBS-016 | B17: 0 | C17: Infraestrutura | D17: Setores pediatricos em diferentes andares aumentando tempo de deslocamento
A18: OBS-017 | B18: 0 | C18: Infraestrutura | D18: Quando um paciente novo chega a UTI, nao ha um aviso programado. A equipe fica sabendo verbalmente
A19: OBS-018 | B19: 0 | C19: Infraestrutura | D19: O pediatra fala sobre o caso com o anestesista verbalmente
A20: OBS-019 | B20: 0 | D20: Reclamacao do tempo acionar o botao-alguem aparecer por parte dos familiares
A21: OBS-020 | B21: 0 | C21: Infraestrutura | D21: Flexibilidade nos horarios de visitas e no numero de pessoas no quarto
A22: OBS-021 | B22: 0 | C22: CERNER | D22: Duplicacao de prescricoes sem algum sistema de aviso
A23: OBS-022 | B23: 0 | D23: Passagem ineficaz de plantao
A24: OBS-023 | B24: 0 | C24: Infraestrutura | D24: Nao comunicacao entre parametros ventilatorios e sistema de prontuario
A25: OBS-024 | B25: 0 | C25: Dispositivos | D25: Quantidade insuficiente de valvulas de O2 no leito
A26: OBS-025 | B26: 0 | D26: Quando ha ECMO na sala nao cabe a famiilia + aparelhos
A27: OBS-026 | B27: 0 | D27: Limpeza de quarto dificultada pela quantidade de coisas.
A28: OBS-027 | B28: 0 | D28: Muito barulho de bombas e alarmes.
A29: OBS-028 | B29: 1 | C29: Equipamentos | D29: Perda de cabos/equipamentos e falta de rastreabilidade dos mesmos
A30: OBS-029 | B30: 1 | C30: CERNER | D30: Muito tempo gasto com registro em prontuario e burocracias
A31: OBS-030 | B31: 1 | C31: Dispositivos | D31: Equipo de dialise tipo aranha
A32: OBS-031 | B32: 1 | C32: Infraestrutura | D32: Falta de um sistema de avisos de altas e admissoes
A33: OBS-032 | B33: 1 | D33: Painel analogico onde e registrado o nivel de complexidade dos pacientes por pontos e codigo de cores
A34: OBS-033 | B34: 1 | D34: Psicologa pouco acionada, abaixo da demanda
A35: OBS-034 | B35: 1 | C35: Dispositivos | D35: A luva e perdida com bastante frequencia e nao funciona bem a partir de um ano e meio de idade nos nao intubados
A36: OBS-035 | B36: 1 | C36: Dispositivos | D36: Luz do laringoscopio falha com facilidade ( travamento com defeito - aciona a lampada atraves de pressao em botao que perde a conexao com o tempo). prejudica iot
A37: OBS-036 | B37: 1 | D37: Bulario feito nao contem todas as medicacoes que usam.
A38: OBS-037 | B38: 1 | C38: Dispositivos | D38: Dificuldade na adaptacao do CNAF
A39: OBS-038 | B39: 1 | C39: Infraestrutura | D39: Uso de leitos destinados para adultos usados em criancas
A40: OBS-039 | B40: 1 | C40: Infraestrutura | D40: Excesso de tempo gasto nas comunicacoes entre profissionais para reforcar o que ja foi feito no sistema
...

Sheet Needs Stage 0
A1: id_filha | B1: id_mae | C1: Potencial (0-3) | D1: Type | E1: Observations | F1: Problem | G1: Population | H1: Intend outcome | I1: Need Statements | J1: Cluster | K1: Nome
A2: NEED-001 | B2: OBS-066 | C2: =VLOOKUP(B2,Observacoes!$A:$D,2,FALSE) | D2: =VLOOKUP(B2,Observacoes!$A:$D,3,FALSE) | E2: =VLOOKUP(B2,Observacoes!$A:$D,4,FALSE) | F2: Comunicacao inefetiva | G2: Criancas internadas na UTI | H2: Melhorar mobilidade | I2: Uma forma de melhorar a comunicacao entre profissionais na UTI pediatrica com o objetivo de reduzir o tempo de resposta ordem-acao em x% | J2: Monitoramento | K2: Ana
A3: NEED-002 | B3: OBS-059 | C3: =VLOOKUP(B3,Observacoes!$A:$D,2,FALSE) | D3: =VLOOKUP(B3,Observacoes!$A:$D,3,FALSE) | E3: =VLOOKUP(B3,Observacoes!$A:$D,4,FALSE) | F3: Excesso de cabos e monitores | G3: Criancas internadas na UTI | H3: Reduzir ansiedade dos pais | I3: Uma forma de otimizar a monitorizacao de sinais vitais em criancas internadas na UTI com o objetivo de aumentar a mobilidade das criancas em x% | J3: Monitoramento | K3: Ana
A4: NEED-003 | B4: OBS-059 | C4: =VLOOKUP(B4,Observacoes!$A:$D,2,FALSE) | D4: =VLOOKUP(B4,Observacoes!$A:$D,3,FALSE) | E4: =VLOOKUP(B4,Observacoes!$A:$D,4,FALSE) | F4: Excesso de cabos e monitores | G4: Criancas internadas na UTI | H4: Antecipar diagnostico sepse | I4: Uma forma de otimizar a monitorizacao de sinais vitais em criancas internadas na UTI com o objetivo de reduzir a ansiedade dos pais dos pacientes em x% | J4: Monitoramento | K4: Ana
A5: NEED-004 | B5: OBS-074 | C5: =VLOOKUP(B5,Observacoes!$A:$D,2,FALSE) | D5: =VLOOKUP(B5,Observacoes!$A:$D,3,FALSE) | E5: =VLOOKUP(B5,Observacoes!$A:$D,4,FALSE) | F5: Afericao de temperatura em intervalos longos (perder picos febris, perder o time de sepse | G5: Criancas internadas na UTI | H5: Antecipar tratamento de infeccoes | I5: Uma forma de prever picos febris em paciente imunosuprimidos oncologicos pediatricos para antecipar o diagnostico de sepse em x %. | J5: Monitoramento | K5: Ana
A6: NEED-005 | B6: OBS-074 | C6: =VLOOKUP(B6,Observacoes!$A:$D,2,FALSE) | D6: =VLOOKUP(B6,Observacoes!$A:$D,3,FALSE) | E6: =VLOOKUP(B6,Observacoes!$A:$D,4,FALSE) | F6: Afericao de temperatura em intervalos longos (perder picos febris, perder o time de infeccoes | G6: Criancas hospitalizadas | H6: Melhores compressoes cardiacas durante RCP | I6: Uma forma de prever picos febris em pacientes imunosuprimidos oncologicos pediatricos para antecipar o tratamento de infeccoes em x% | J6: Monitoramento | K6: Ana
A7: NEED-006 | B7: OBS-075 | C7: =VLOOKUP(B7,Observacoes!$A:$D,2,FALSE) | D7: =VLOOKUP(B7,Observacoes!$A:$D,3,FALSE) | E7: =VLOOKUP(B7,Observacoes!$A:$D,4,FALSE) | F7: Capnografo inadequados para criancas pequenas | G7: Criancas internadas na UTI | H7: Melhor ajuste ventilatorio | I7: Uma nova forma de monitorizar o ETCO2 em pacientes criticos pediatricos para tornar as compressoes cardiacas mais efetivas em x% durante as PCRs | J7: Monitoramento | K7: Ana
A8: NEED-007 | B8: OBS-075 | C8: =VLOOKUP(B8,Observacoes!$A:$D,2,FALSE) | D8: =VLOOKUP(B8,Observacoes!$A:$D,3,FALSE) | E8: =VLOOKUP(B8,Observacoes!$A:$D,4,FALSE) | F8: Capnografo inadequados para criancas pequenas | G8: Criancas internadas na UTI | H8: Melhorar mobilidade | I8: Uma nova forma de monitorizar o ETCO2 em pacientes criticos pediatricos para reduzir o tempo de desmame ventilatorio em x% | J8: Monitoramento | K8: Ana
A9: NEED-008 | B9: OBS-086 | C9: =VLOOKUP(B9,Observacoes!$A:$D,2,FALSE) | D9: =VLOOKUP(B9,Observacoes!$A:$D,3,FALSE) | E9: =VLOOKUP(B9,Observacoes!$A:$D,4,FALSE) | F9: Equipamento de EEG grande e sem conexao com outros monitores | G9: Criancas internadas na UTI | H9: Evitar acidentes com as bombas de infusao | I9: Uma nova forma de monitorizar ondas cerebrais em pacientes pediatricos com objetivo de melhorar a mobilidade em x% | J9: Monitoramento | K9: Ana
A10: NEED-009 | B10: OBS-087 | C10: =VLOOKUP(B10,Observacoes!$A:$D,2,FALSE) | D10: =VLOOKUP(B10,Observacoes!$A:$D,3,FALSE) | E10: =VLOOKUP(B10,Observacoes!$A:$D,4,FALSE) | F10: Bombas e suportes de bombas inadequados para essa populacao | G10: Criancas internadas | H10: Reduzir o tempo gasto com ajustes | I10: Uma forma de infundir medicacoes em pacientes pediatricos internados com o objetivo de melhorar a mobilidade das criancas em x% | J10: Medicamentos | K10: Ana
A11: NEED-010 | B11: OBS-087 | C11: =VLOOKUP(B11,Observacoes!$A:$D,2,FALSE) | D11: =VLOOKUP(B11,Observacoes!$A:$D,3,FALSE) | E11: =VLOOKUP(B11,Observacoes!$A:$D,4,FALSE) | F11: Bombas e suportes de bombas inadequados para essa populacao | G11: Criancas internadas | H11: Evitar erros de dosagem | I11: Uma forma de infundir medicacoes em pacientes pediatricos internados com o objetivo de tornar esse processo mais seguro em x% (evitar erros graves evitaveis) | J11: Medicamentos | K11: Ana
A12: NEED-011 | B12: OBS-090 | C12: =VLOOKUP(B12,Observacoes!$A:$D,2,FALSE) | D12: =VLOOKUP(B12,Observacoes!$A:$D,3,FALSE) | E12: =VLOOKUP(B12,Observacoes!$A:$D,4,FALSE) | F12: Ajuste de bombas realizados de forma manual | G12: Criancas internadas na UTI | H12: Reduzir complicacoes de RE-IOT | I12: Uma forma de automatizar as bombas de infusao das UTIs pediatricas com o objetivo de otimizar o tempo da enfermagem em x% | J12: Medicamentos | K12: Ana
A13: NEED-012 | B13: OBS-090 | C13: =VLOOKUP(B13,Observacoes!$A:$D,2,FALSE) | D13: =VLOOKUP(B13,Observacoes!$A:$D,3,FALSE) | E13: =VLOOKUP(B13,Observacoes!$A:$D,4,FALSE) | F13: Ajuste de bombas realizados de forma manual | G13: Criancas internadas na UTI | H13: Reduzir RE-IOT | I13: Uma forma de automatizar as bombas de infusao das UTIs pediatricas com o objetivo de evitar erros de processo em x% | J13: Medicamentos | K13: Ana
... A30: NEED-029 | B30: OBS-091 | C30: =VLOOKUP(B30,Observacoes!$A:$D,2,FALSE) | D30: =VLOOKUP(B30,Observacoes!$A:$D,3,FALSE) | E30: =VLOOKUP(B30,Observacoes!$A:$D,4,FALSE) | F30: Caterer nao fixado aumenta chande de perda de cateteres e necessidade de nova puncao | G30: Criancas hospitalizadas | H30: Reduzir as taxas de perda de cateter venoso causadas pelas maos da crianca | I30: Uma forma de fixar cateter e reduzir EM % as taxas de perda de cateter venoso causada pelos movimentos da crianca | J30: Cateter | K30: Mariana
A31: NEED-030 | C31: 3 | D31: Fixacao e cateteres | E31: nao ha uma fixacao de Dreno de torax especifica para criancas (algo feito e montado com tensoplast ( pode machucar) | F31: Causa exulceracoes e lesao por pressao. | G31: Criancas hospitalizadas | H31: A falta de fixacao voltada pra criancas obriga a fazer dispositivo nao padrao que pode lesionar a pele do paciente. | I31: Uma forma de fixar dreno em criancas reduzindo as lesoes cutaneas pela fixacao em x%. | J31: Derme | K31: Mariana
A32: NEED-031 | B32: OBS-076 | C32: =VLOOKUP(B32,Observacoes!$A:$D,2,FALSE) | D32: =VLOOKUP(B32,Observacoes!$A:$D,3,FALSE) | E32: =VLOOKUP(B32,Observacoes!$A:$D,4,FALSE) | F32: Erro de medicacao | G32: Criancas hospitalizadas | H32: Reduzir os efeitos adversos e a necessidade de intervir no paciente para resolve-los | I32: Uma forma de reduzir erros de medicacao graves evitaveis em pacientes pediatricos hospitalizados com o objetivo de reduzir os custos hospitalares associados em x% (efeitos adversos diretos, reacoes alergicas, danos organicos, resistencia a antibioticos, danos cognitivos ou do desenvolvimento, impacto emocional e psicologico) | J32: Medicamentos | K32: Marta
A33: NEED-032 | B33: OBS-083 | C33: =VLOOKUP(B33,Observacoes!$A:$D,2,FALSE) | D33: =VLOOKUP(B33,Observacoes!$A:$D,3,FALSE) | E33: =VLOOKUP(B33,Observacoes!$A:$D,4,FALSE) | F33: Efeitos colaterais do uso de sedativos | G33: Criancas internadas na UTI | H33: Reduzir os efeitos adversos e a necessidade de intervir no paciente para resolve-los | I33: Uma forma de reduzir o uso de sedacao em pacientes pediatricos internados na UTI com o objetivo de reduzir a morbidade em X% (pneumonia, ulceras de pressao, miopatia, trombose venosa profunda) | J33: Medicamentos | K33: Marta
A34: NEED-033 | C34: 3 | D34: Medicamentos | E34: nao ha uma forma de diferenciar entre tolerancia a droga/ abstinencia x delirium em criancas que estao em uso prolongado de sedativos. Usam escalas comportamentais, mas as criancas puntuam os dois. Na pratica tratam as duas coisas. | F34: Nao ha diagnostico diferencial entre tolerancia a droga e delirium | G34: Criancas internadas na UTI | H34: Reduzir os efeitos adversos associados a um erro de diagnostico | I34: Uma forma de diferenciar entre delirum e tolerancia a droga em pacientes pediatricos sedados internados em UTI com quadro de agitacao com o objetivo de reduzir hipersedacao em X% | J34: Medicamentos | K34: Marta
A35: NEED-034 | C35: 3 | D35: Medicamentos | E35: nao ha uma forma de diferenciar entre tolerancia a droga/ abstinencia x delirium em criancas que estao em uso prolongado de sedativos. Usam escalas comportamentais, mas as criancas puntuam os dois. Na pratica tratam as duas coisas. | F35: Nao ha diagnostico diferencial entre tolerancia a droga e delirium | G35: Criancas internadas na UTI | H35: Reduzir os efeitos adversos associados a um erro de diagnostico | I35: Uma forma de diferenciar entre delirum e tolerancia a droga em pacientes pediatricos sedados internados em UTI com quadro de agitacao com o objetivo de reduzir intervencoes innecesarias em X% | J35: Medicamentos | K35: Marta
A36: NEED-035 | B36: OBS-089 | C36: =VLOOKUP(B36,Observacoes!$A:$D,2,FALSE) | D36: =VLOOKUP(B36,Observacoes!$A:$D,3,FALSE) | E36: =VLOOKUP(B36,Observacoes!$A:$D,4,FALSE) | F36: Nao ha metodo eficaz para titulacao de niveis de sedacao | G36: Criancas internadas na UTI | H36: Reduzir a morbidade associada a niveis de sedacao subotimos | I36: Uma forma de controlar o nivel de sedacao em pacientes pediatricos internados na UTI para reduzir a morbidade em X% (pneumonia, ulceras de pressao, miopatia, trombose venosa profunda, delirium) | J36: Medicamentos | K36: Marta
A37: NEED-036 | C37: 3 | D37: Medicamentos | E37: Reducao de mobilidade por conta de infusao de medicamentos por muito tempo | F37: Perda de liberdade de movimento causa atrofia e perda muscular. | G37: Criancas hospitalizadas | H37: Reducao de mobilidade causa Perda de Forca Muscular e Atrofia | I37: Uma forma melhorar a administracao de medicamentos com o objetivo de melhorar mobilidade | J37: Medicamentos | K37: Mariana
A38: NEED-037 | B38: OBS-073 | C38: =VLOOKUP(B38,Observacoes!$A:$D,2,FALSE) | D38: =VLOOKUP(B38,Observacoes!$A:$D,3,FALSE) | E38: =VLOOKUP(B38,Observacoes!$A:$D,4,FALSE) | F38: Favorece o surgimento de Infeccao da Corrente Sanguinea Associada ao Cateter Central (CLABSI) | G38: Criancas hospitalizadas | H38: Reduzir infeccao de cateter | I38: Uma forma de reduzir a administracao de medicamentos por via intravenosa reduzindo a taxa de infeccao de cateter em % ( cateter central e periferico, infeccao sistemica) | J38: Medicamentos | K38: Mariana
A39: NEED-038 | B39: OBS-073 | C39: =VLOOKUP(B39,Observacoes!$A:$D,2,FALSE) | D39: =VLOOKUP(B39,Observacoes!$A:$D,3,FALSE) | E39: =VLOOKUP(B39,Observacoes!$A:$D,4,FALSE) | F39: A administracao de grandes quantidades de emdicamentos intravenosos aumenta o risco de flebite e tromboflebite | G39: Criancas hospitalizadas | H39: Reduzir as taxas de flebite e tromboflebite em criancas internadas na uti | I39: Uma forma de reduzir a administracao de medicamentos por via intravenosa periferica reduzindo a taxa tromboflebite/flebite em % (local) | J39: Medicamentos | K39: Mariana
A40: NEED-039 | B40: OBS-077 | C40: =VLOOKUP(B40,Observacoes!$A:$D,2,FALSE) | D40: =VLOOKUP(B40,Observacoes!$A:$D,3,FALSE) | E40: =VLOOKUP(B40,Observacoes!$A:$D,4,FALSE) | F40: Falta de movimento causa morbidade | G40: Criancas hospitalizadas e domiciliares | H40: Reduzir riscos associados a falta de mobilidade | I40: Uma forma de dializar em pacientes hospitalares e domiciliares que permita reduzir os riscos associados a imobilidade em X% (ulceras de pressao, miopatia, trombose venosa profunda). | J40: Derme | K40: Marta
A41: NEED-040 | B41: OBS-081 | C41: =VLOOKUP(B41,Observacoes!$A:$D,2,FALSE) | D41: =VLOOKUP(B41,Observacoes!$A:$D,3,FALSE) | E41: =VLOOKUP(B41,Observacoes!$A:$D,4,FALSE) | F41: Falta de movimento causa deterioracao no desenvolvimento cognitivo e motor | G41: Criancas hospitalizadas de 0 a 1 ano | H41: Reduzir efeitos negativos no desenvolvimento cognitivo e motor | I41: Uma forma de melhorar a mobilidade em pacientes pediatricos hospitalizados entre 0 e 1 ano para reduzir o atraso no desenvolvimento cognitivo e motor em X% | J41: Mobilidade | K41: Marta
A42: NEED-041 | B42: OBS-067 | C42: =VLOOKUP(B42,Observacoes!$A:$D,2,FALSE) | D42: =VLOOKUP(B42,Observacoes!$A:$D,3,FALSE) | E42: =VLOOKUP(B42,Observacoes!$A:$D,4,FALSE) | F42: Atraso entre a medida real da saturacao de oxigenio e a exibicao na tela | G42: Criancas hospitalizadas | H42: Reduzir falta ou atraso na deteccao de episodios de insuficiencia respiratoria | I42: Uma forma de melhorar as medidas de saturacao de oxigenio em pacientes pediatricos hospitalizados com o objetivo de reduzir o tempo de demora em identificacao de hipoxemia X% | J42: Respiratorio | K42: Marta
A43: NEED-042 | B43: OBS-065 | C43: =VLOOKUP(B43,Observacoes!$A:$D,2,FALSE) | D43: =VLOOKUP(B43,Observacoes!$A:$D,3,FALSE) | E43: =VLOOKUP(B43,Observacoes!$A:$D,4,FALSE) | F43: Atraso no diagnostico de bronquiolite gera morbidade | G43: Criancas hospitalizadas e domiciliares | H43: Reduzir atraso no diagnostico e custo associado na gestao das morbidades provocadas pelo mesmo | I43: Uma forma de melhorar o diagnostico de bronqueolite em pacientes pediatricos hospitalizados e domiciliares con el objetivo de antecipar o cuidado (reducir internacao) em um %X | J43: Respiratorio | K43: Marta
A44: NEED-043 | C44: 3 | D44: Patologias | E44: Sarcopenia infantil | F44: Sarcopenia infantil | G44: Criancas hospitalizadas | H44: Reduzir morbidades associadas | I44: Uma forma de reduzir a imobilidade infantil en pacientes pediatricos hospitalizados com el objetivo de reducir a sarcopenia em um X% | J44: Mobilidade | K44: Marta
A45: NEED-044 | C45: 3 | D45: Patologias | E45: Crises convulsivas | F45: Imprevisibilidade das crises Perca de consciencia | G45: criancas | H45: inibir crises em x% | I45: Uma nova forma de aumentar a previsibilidade das crises convulsivas em pacientes pediatricos com o objetivo de inibir crises em x% | J45: Monitoramento | K45: Vitor
A46: NEED-045 | C46: 3 | D46: Patologias | E46: Enterocolite necrotizando | F46: Perca da funcao intestinal | G46: recem-nascidos | H46: reduzir chance de necrose em x% | I46: Uma forma de reduzir a perca de funcao intestinal em pacientes pediatricos com o objetivo de reduzir a chance de necrose em x% | J46: Derme | K46: Vitor
A47: NEED-046 | B47: OBS-060 | C47: =VLOOKUP(B47,Observacoes!$A:$D,2,FALSE) | D47: =VLOOKUP(B47,Observacoes!$A:$D,3,FALSE) | E47: =VLOOKUP(B47,Observacoes!$A:$D,4,FALSE) | F47: Agitacao Tamanho agulha Baixa margem para erro | G47: criancas | H47: reduzir eventos adversos em x% | I47: Uma forma de reduzir acidentes de puncao em pacientes pediatricos com o objetivo de reduzir eventos adversos em x% | J47: Cateter | K47: Vitor
A48: NEED-047 | B48: OBS-061 | C48: =VLOOKUP(B48,Observacoes!$A:$D,2,FALSE) | D48: =VLOOKUP(B48,Observacoes!$A:$D,3,FALSE) | E48: =VLOOKUP(B48,Observacoes!$A:$D,4,FALSE) | F48: Identificacao da veia Maos ocupadas com ultrasom e agulha | G48: criancas | H48: reduzir eventos adversos em x% | I48: Uma forma de melhorar a identificaca de veias em pacientes pediatricos com o objetivo de reduzir eventos adversos em x% | J48: Cateter | K48: Vitor
A49: NEED-048 | B49: OBS-062 | C49: =VLOOKUP(B49,Observacoes!$A:$D,2,FALSE) | D49: =VLOOKUP(B49,Observacoes!$A:$D,3,FALSE) | E49: =VLOOKUP(B49,Observacoes!$A:$D,4,FALSE) | F49: Infeccao do cateter | G49: criancas | H49: reduzir as taxas de infeccoes em x% | I49: Uma forma protetiva de inserir o cateter em pacientes pediatricos com o objetivo de reduzir a infeccao do cateter em x% | J49: Cateter | K49: Vitor
A50: NEED-049 | B50: OBS-070 | C50: =VLOOKUP(B50,Observacoes!$A:$D,2,FALSE) | D50: =VLOOKUP(B50,Observacoes!$A:$D,3,FALSE) | E50: =VLOOKUP(B50,Observacoes!$A:$D,4,FALSE) | F50: Dores na mao Facil desconexao | G50: criancas | H50: diminuir as desconexoes acidentais em x% | I50: Uma melhor forma de PAI em pacientes pediatricos com o objetivo de diminuir as desconexoes acidentais em x% | J50: Cateter | K50: Vitor
A51: NEED-050 | B51: OBS-071 | C51: =VLOOKUP(B51,Observacoes!$A:$D,2,FALSE) | D51: =VLOOKUP(B51,Observacoes!$A:$D,3,FALSE) | E51: =VLOOKUP(B51,Observacoes!$A:$D,4,FALSE) | F51: Fixacao machuca Fixacao inadequado impede funcionamento | G51: criancas | H51: operabilidade da sonda em % | I51: Uma melhor forma de fixacao da sonda vesical em pacientes pediatricos com o objetivo de manter a operabilidade da sonda em 100% | J51: Cateter | K51: Vitor
A52: NEED-051 | B52: OBS-072 | C52: =VLOOKUP(B52,Observacoes!$A:$D,2,FALSE) | D52: =VLOOKUP(B52,Observacoes!$A:$D,3,FALSE) | E52: =VLOOKUP(B52,Observacoes!$A:$D,4,FALSE) | F52: Intervencao cirurgica Inefetividade da sonda por falta de tamanho | G52: criancas | H52: reduzir intervencoes cirurgicas em x% | I52: Uma melhor forma de adequar a sonda vesical de demora em pacientes pediatricos com o objetivo de reduzir intervencoes cirurgicas em x% | J52: Cateter | K52: Vitor
A53: NEED-052 | B53: OBS-092 | C53: =VLOOKUP(B53,Observacoes!$A:$D,2,FALSE) | D53: =VLOOKUP(B53,Observacoes!$A:$D,3,FALSE) | E53: =VLOOKUP(B53,Observacoes!$A:$D,4,FALSE) | F53: PICC ir para um lugar indesejado | G53: criancas | H53: reduzir eventos adversos em x% | I53: Uma forma de rastreabilidade do caminho do PIC em pacientes pediatricos com o objetivo de reduzir eventos adversos em x% | J53: Cateter | K53: Vitor
A54: NEED-053 | B54: OBS-050 | C54: =VLOOKUP(B54,Observacoes!$A:$D,2,FALSE) | D54: =VLOOKUP(B54,Observacoes!$A:$D,3,FALSE) | E54: =VLOOKUP(B54,Observacoes!$A:$D,4,FALSE) | F54: Dificuldade de comunicacao entre equipe e familiares | G54: Criancas internadas na UTI | H54: Evitar repeticao de conversas ja realizadas | I54: Uma forma de facilitar o entendimento dos familiares de criancas internadas em UTIs pediatricas para evitar chamados desnecessarios em x% | J54: Monitoramento | K54: Ana
A55: NEED-054 | B55: OBS-055 | C55: =VLOOKUP(B55,Observacoes!$A:$D,2,FALSE) | D55: =VLOOKUP(B55,Observacoes!$A:$D,3,FALSE) | E55: =VLOOKUP(B55,Observacoes!$A:$D,4,FALSE) | F55: Desperdicio de dinheiro | G55: Criancas hospitalizadas | H55: Viabilizar um dispositivo que seja possivel trocar baterias ou pilhas | I55: Uma forma de Viabilizar um dispositivo que seja possivel trocar baterias ou pilhas | J55: Monitoramento | K55: Mariana
A56: NEED-055 | B56: OBS-056 | C56: =VLOOKUP(B56,Observacoes!$A:$D,2,FALSE) | D56: =VLOOKUP(B56,Observacoes!$A:$D,3,FALSE) | E56: =VLOOKUP(B56,Observacoes!$A:$D,4,FALSE) | F56: Dificuldade de transporte | H56: Melhorar/aperfeicoar eco para uma aparelhagem completa. | I56: Uma forma de Melhorar/aperfeicoar eco para uma aparelhagem completa. | J56: Monitoramento | K56: Mariana
...
